### 🛡️ try-catch 表达式

```kotlin
fun test(): Int {
    val result = try {
        // 模拟可能抛出 ArithmeticException 的操作
        10 / (0..1).random()
    } catch (e: ArithmeticException) {
        throw IllegalStateException(e)
    }

    // 使用 result
    println(result)
    return result
}

fun main() {
    try {
        val result = test()
        println("操作成功，结果为: $result")
    } catch (e: IllegalStateException) {
        println("捕获到异常: ${e.message}")
    }
}


// 10
// 操作成功，结果为: 10

// 或

// 捕获到异常: java.lang.ArithmeticException: / by zero

```